Workbook

Sheet Pages
A1: IPP Next 39 Priorities: Landing Page Status Tracker (40 pages)
A2: Source list: 'Priority Equipment Types - Next 39 Priorities (1-39).xlsx' (client, 2026-10-01). Priority 19 (Dryer-Air) is two pages, so 39 priorities = 40 pages. Batch 0 = the approved pilot. Yellow columns are for the IPP team to edit; everything else is maintained by the build.
A4: Priority | B4: Batch | C4: Client Group | D4: Client Subgroup | E4: Page | F4: Live / Proposed URL | G4: IMS Category | H4: IMS Listing Count | I4: Units on Page | J4: Units with Photos | K4: Primary Keyword | L4: Primary KW Volume (US) | M4: IMS Inventory Scrape | N4: Query Network (Ahrefs) | O4: Content Written | P4: Content Checks | Q4: Page Built | R4: Client Review Doc | S4: Deployed to Vercel | T4: Overall Status | U4: Client Review | V4: Review Page (Vercel) | W4: Repo Page | X4: Last Updated | Y4: Notes / Risks
A5: 1 | B5: 1 | C5: Centrifuge-Lab | E5: Lab Centrifuges | F5: https://internationalprocessplants.com/process-equipment/centrifuge/lab-centrifuge/ | G5: https://ims.internationalprocessplants.com/inventory/search/equipment/lab-centrifuge | H5: 5 | I5: 5 | J5: 5 | K5: lab centrifuge | L5: 800 | M5: Done | N5: Done | O5: Done | P5: Done | Q5: Done | R5: Done | S5: Done | T5: =IF(COUNTIF(M5:S5,"Done")+COUNTIF(M5:S5,"N/A")=7,"Ready for client review",IF(COUNTIF(M5:S5,"Blocked")>0,"Blocked",IF(COUNTIF(M5:S5,"Not started")=7,"Not started","In progress"))) -> Ready for client review | U5: Not sent | V5: https://international-process-plants-update-one.vercel.app/equipment/centrifuge/lab-centrifuge/ | W5: equipment/centrifuge/lab-centrifuge/INTERNAL-REVIEW-lab-centrifuge.html | X5: 2026-10-02 | Y5: Built. Only 5 units, all process-scale (Carr Centritech Centritec Cell 8, Sharples Type 1P, a beaker centrifuge), not benchtop instruments; the copy says so. 'lab centrifuge' and 'ultracentrifuge' demand is lab-instrument (Beckman, Thermo), so the ultracentrifuge terms are excluded. No size or condition tabs (all used). 2026-10-02: live hero, logo strip and tabs; blog and intro links removed; hero predicates varied. Hero opener rewritten on 2026-10-02 to the client's 'Buying ... from IPP [verb] ... while [verb]ing issues like ...' format; review doc re-issued. Live white header with the IPP logo and menu added on 2026-10-02 (adbac2f).
A6: 2 | B6: 1 | C6: Centrifuge-Misc. & Hydraulic | E6: Hydraulic and Miscellaneous Centrifuges | F6: https://internationalprocessplants.com/process-equipment/centrifuge/misc-and-hydraulic-centrifuge/ | G6: https://ims.internationalprocessplants.com/inventory/search/equipment/misc-and-hydraulic-centrifuge | H6: 38 | I6: 38 | J6: 35 | K6: tubular centrifuge | L6: 70 | M6: Done | N6: Done | O6: Done | P6: Done | Q6: Done | R6: Done | S6: Done | T6: =IF(COUNTIF(M6:S6,"Done")+COUNTIF(M6:S6,"N/A")=7,"Ready for client review",IF(COUNTIF(M6:S6,"Blocked")>0,"Blocked",IF(COUNTIF(M6:S6,"Not started")=7,"Not started","In progress"))) -> Ready for client review | U6: Not sent | V6: https://international-process-plants-update-one.vercel.app/equipment/centrifuge/misc-and-hydraulic-centrifuge/ | W6: equipment/centrifuge/misc-and-hydraulic-centrifuge/INTERNAL-REVIEW-misc-and-hydraulic-centrifuge.html | X6: 2026-10-02 | Y6: Built as 'Tubular, Podbielniak & Hydraulic Centrifuges': IMS's misc bucket is Sharples tubular super centrifuges, Podbielniak extractors and hydraulic drives. 'Hydraulic centrifuge' has no search demand; the page targets tubular / super / sharples / centrifugal extractor. 2026-10-02: live hero, logo strip and tabs; blog and intro links removed; hero predicates varied. Hero opener rewritten on 2026-10-02 to the client's 'Buying ... from IPP [verb] ... while [verb]ing issues like ...' format; review doc re-issued. Live white header with the IPP logo and menu added on 2026-10-02 (adbac2f).
A7: 3 | B7: 1 | C7: Centrifuge-Peeler | E7: Peeler Centrifuges | F7: https://internationalprocessplants.com/process-equipment/centrifuge/peeler-centrifuge/ | G7: https://ims.internationalprocessplants.com/inventory/search/equipment/peeler-centrifuge | H7: 49 | I7: 49 | J7: 49 | K7: peeler centrifuge | L7: 150 | M7: Done | N7: Done | O7: Done | P7: Done | Q7: Done | R7: Done | S7: Done | T7: =IF(COUNTIF(M7:S7,"Done")+COUNTIF(M7:S7,"N/A")=7,"Ready for client review",IF(COUNTIF(M7:S7,"Blocked")>0,"Blocked",IF(COUNTIF(M7:S7,"Not started")=7,"Not started","In progress"))) -> Ready for client review | U7: Not sent | V7: https://international-process-plants-update-one.vercel.app/equipment/centrifuge/peeler-centrifuge/ | W7: equipment/centrifuge/peeler-centrifuge/INTERNAL-REVIEW-peeler-centrifuge.html | X7: 2026-10-02 | Y7: Built. IPP's blog already ranks for 'what is a peeler centrifuge' and 'peeler vs pusher', so the FAQ answers briefly and links to those guides. 2026-10-02: live hero, logo strip and tabs; blog and intro links removed; hero predicates varied. Hero opener rewritten on 2026-10-02 to the client's 'Buying ... from IPP [verb] ... while [verb]ing issues like ...' format; review doc re-issued. Live white header with the IPP logo and menu added on 2026-10-02 (adbac2f).
A8: 4 | B8: 1 | C8: Centrifuge-Pusher | D8: Parts Only | E8: Pusher Centrifuge Parts | F8: https://internationalprocessplants.com/process-equipment/centrifuge/pusher-centrifuge-parts/ | G8: https://ims.internationalprocessplants.com/inventory/search/equipment/pusher-centrifuge/parts-only | H8: 21 | I8: 21 | J8: 1 | K8: pusher centrifuge parts | L8: 40 | M8: Done | N8: Done | O8: Done | P8: Done | Q8: Done | R8: Done | S8: Done | T8: =IF(COUNTIF(M8:S8,"Done")+COUNTIF(M8:S8,"N/A")=7,"Ready for client review",IF(COUNTIF(M8:S8,"Blocked")>0,"Blocked",IF(COUNTIF(M8:S8,"Not started")=7,"Not started","In progress"))) -> Ready for client review | U8: Not sent | V8: https://international-process-plants-update-one.vercel.app/equipment/centrifuge/pusher-centrifuge-parts/ | W8: equipment/centrifuge/pusher-centrifuge-parts/INTERNAL-REVIEW-pusher-centrifuge-parts.html | X8: 2026-10-02 | Y8: Built. 21 parts listings, only 1 with a photo, mostly Krauss Maffei SB1000/2 components. Part type comes from the IMS description, and browse cards use IMS keyword search. Generic 'centrifuge parts' demand is lab-instrument parts, so it is excluded. 2026-10-02: live hero, logo strip and tabs; blog and intro links removed; hero predicates varied. Hero opener rewritten on 2026-10-02 to the client's 'Buying ... from IPP [verb] ... while [verb]ing issues like ...' format; review doc re-issued. Live white header with the IPP logo and menu added on 2026-10-02 (adbac2f).
A9: 5 | B9: 1 | C9: Centrifuge-Pusher | E9: Pusher Centrifuges | F9: https://internationalprocessplants.com/process-equipment/centrifuge/pusher-centrifuge/ | G9: https://ims.internationalprocessplants.com/inventory/search/equipment/pusher-centrifuge | H9: 47 | I9: 26 | J9: 26 | K9: pusher centrifuge | L9: 150 | M9: Done | N9: Done | O9: Done | P9: Done | Q9: Done | R9: Done | S9: Done | T9: =IF(COUNTIF(M9:S9,"Done")+COUNTIF(M9:S9,"N/A")=7,"Ready for client review",IF(COUNTIF(M9:S9,"Blocked")>0,"Blocked",IF(COUNTIF(M9:S9,"Not started")=7,"Not started","In progress"))) -> Ready for client review | U9: Not sent | V9: https://international-process-plants-update-one.vercel.app/equipment/centrifuge/pusher-centrifuge/ | W9: equipment/centrifuge/pusher-centrifuge/INTERNAL-REVIEW-pusher-centrifuge.html | X9: 2026-10-02 | Y9: Built from 26 complete machines (the 21 parts-only listings are on priority 4). The IMS 'Browse All' links show IMS's own pusher search, which includes the parts. 2026-10-02: live hero, logo strip and tabs; blog and intro links removed; hero predicates varied. Hero opener rewritten on 2026-10-02 to the client's 'Buying ... from IPP [verb] ... while [verb]ing issues like ...' format; review doc re-issued. Live white header with the IPP logo and menu added on 2026-10-02 (adbac2f).
A10: 6 | B10: 2 | C10: Centrifuge-Solid Bowl-Decanter | D10: Parts Only | E10: Decanter Centrifuge Parts | F10: https://internationalprocessplants.com/process-equipment/centrifuge/solid-bowl-decanter-centrifuge-parts/ | G10: https://ims.internationalprocessplants.com/inventory/search/equipment/solid-bowl-decanter-centrifuge/parts-only | H10: 7 | I10: 7 | J10: 7 | K10: decanter centrifuge parts | L10: 10 | M10: Done | N10: Done | O10: Done | P10: Done | Q10: Done | R10: Done | S10: Done | T10: =IF(COUNTIF(M10:S10,"Done")+COUNTIF(M10:S10,"N/A")=7,"Ready for client review",IF(COUNTIF(M10:S10,"Blocked")>0,"Blocked",IF(COUNTIF(M10:S10,"Not started")=7,"Not started","In progress"))) -> Ready for client review | U10: Not sent | V10: https://international-process-plants-update-one.vercel.app/equipment/centrifuge/solid-bowl-decanter-centrifuge-parts/ | W10: equipment/centrifuge/solid-bowl-decanter-centrifuge-parts/INTERNAL-REVIEW-solid-bowl-decanter-centrifuge-parts.html | X10: 2026-10-02 | Y10: Built. 7 parts listings, all with photos: scroll conveyors (Sharples P3400, Alfa Laval NX314, Dorr Oliver for the 16L and Z3L), Sharples P-2000 and Sangerhausen rotating assemblies, and a Bird gearbox. Part type comes from the IMS description. Complete-machine and repair queries are excluded (the live decanter page owns machines). Hero opener rewritten on 2026-10-02 to the client's 'Buying ... from IPP [verb] ... while [verb]ing issues like ...' format; review doc re-issued. Live white header with the IPP logo and menu added on 2026-10-02 (adbac2f).
A11: 7 | B11: 2 | C11: Dryer- Nauta / Conical | E11: Nauta Dryers | F11: https://internationalprocessplants.com/process-equipment/dryer/nauta-dryer/ | G11: https://ims.internationalprocessplants.com/inventory/search/equipment/nauta-dryer | H11: 11 | I11: 11 | J11: 11 | K11: nauta dryer | L11: 150 | M11: Done | N11: Done | O11: Done | P11: Done | Q11: Done | R11: Done | S11: Done | T11: =IF(COUNTIF(M11:S11,"Done")+COUNTIF(M11:S11,"N/A")=7,"Ready for client review",IF(COUNTIF(M11:S11,"Blocked")>0,"Blocked",IF(COUNTIF(M11:S11,"Not started")=7,"Not started","In progress"))) -> Ready for client review | U11: Not sent | V11: https://international-process-plants-update-one.vercel.app/equipment/dryer/nauta-dryer/ | W11: equipment/dryer/nauta-dryer/INTERNAL-REVIEW-nauta-dryer.html | X11: 2026-10-02 | Y11: Built. 11 units from 9 OEMs (Krauss Maffei, Bolz, Vrieco Nauta, Hosokawa Alpine and others). Nauta mixer terms are excluded (the live Nauta mixer page owns them); double cone terms belong to the twin shell page, linked from the comparison table. Hero opener rewritten on 2026-10-02 to the client's 'Buying ... from IPP [verb] ... while [verb]ing issues like ...' format; review doc re-issued. Live white header with the IPP logo and menu added on 2026-10-02 (adbac2f).
A12: 8 | B12: 2 | C12: Dryer-Drum | E12: Drum Dryers | F12: https://internationalprocessplants.com/process-equipment/dryer/drum-dryer/ | G12: https://ims.internationalprocessplants.com/inventory/search/equipment/drum-dryer | H12: 16 | I12: 16 | J12: 16 | K12: drum dryer | L12: 300 | M12: Done | N12: Done | O12: Done | P12: Done | Q12: Done | R12: Done | S12: Done | T12: =IF(COUNTIF(M12:S12,"Done")+COUNTIF(M12:S12,"N/A")=7,"Ready for client review",IF(COUNTIF(M12:S12,"Blocked")>0,"Blocked",IF(COUNTIF(M12:S12,"Not started")=7,"Not started","In progress"))) -> Ready for client review | U12: Not sent | V12: https://international-process-plants-update-one.vercel.app/equipment/dryer/drum-dryer/ | W12: equipment/dryer/drum-dryer/INTERNAL-REVIEW-drum-dryer.html | X12: 2026-10-02 | Y12: Built. 16 listings: Simon Dryers, Blaw Knox and Gouda single and double drum dryers plus unused spare drums. Household laundry dryer and rotary drum dryer terms are excluded. Hero opener rewritten on 2026-10-02 to the client's 'Buying ... from IPP [verb] ... while [verb]ing issues like ...' format; review doc re-issued. Live white header with the IPP logo and menu added on 2026-10-02 (adbac2f).
A13: 9 | B13: 2 | C13: Dryer-Flash | E13: Flash Dryers | F13: https://internationalprocessplants.com/process-equipment/dryer/flash-dryer/ | G13: https://ims.internationalprocessplants.com/inventory/search/equipment/flash-dryer | H13: 4 | I13: 4 | J13: 4 | K13: industrial flash dryer | L13: 40 | M13: Done | N13: Done | O13: Done | P13: Done | Q13: Done | R13: Done | S13: Done | T13: =IF(COUNTIF(M13:S13,"Done")+COUNTIF(M13:S13,"N/A")=7,"Ready for client review",IF(COUNTIF(M13:S13,"Blocked")>0,"Blocked",IF(COUNTIF(M13:S13,"Not started")=7,"Not started","In progress"))) -> Ready for client review | U13: Not sent | V13: https://international-process-plants-update-one.vercel.app/equipment/dryer/flash-dryer/ | W13: equipment/dryer/flash-dryer/INTERNAL-REVIEW-flash-dryer.html | X13: 2026-10-02 | Y13: Built (new URL, no live page). Only 4 units: APV Anhydro spin flash, Aljet, Hosokawa Alpine MDV-4, AKSH Engineering. Screen-printing flash dryers dominate 'flash dryer' demand, so the H1 says industrial. The IMS inlet-moisture fields and the Hosokawa evaporation field are mislabelled, so they are not published. Hero opener rewritten on 2026-10-02 to the client's 'Buying ... from IPP [verb] ... while [verb]ing issues like ...' format; review doc re-issued. Live white header with the IPP logo and menu added on 2026-10-02 (adbac2f).
A14: 10 | B14: 2 | C14: Dryer-Porcupine | D14: Parts | E14: Porcupine Dryer Parts | F14: https://internationalprocessplants.com/process-equipment/dryer/porcupine-dryer-parts/ | G14: https://ims.internationalprocessplants.com/inventory/search/equipment/porcupine-dryer/parts | H14: 4 | I14: 4 | J14: 2 | K14: porcupine dryer parts | M14: Done | N14: Done | O14: Done | P14: Done | Q14: Done | R14: Done | S14: Done | T14: =IF(COUNTIF(M14:S14,"Done")+COUNTIF(M14:S14,"N/A")=7,"Ready for client review",IF(COUNTIF(M14:S14,"Blocked")>0,"Blocked",IF(COUNTIF(M14:S14,"Not started")=7,"Not started","In progress"))) -> Ready for client review | U14: Not sent | V14: https://international-process-plants-update-one.vercel.app/equipment/dryer/porcupine-dryer-parts/ | W14: equipment/dryer/porcupine-dryer-parts/INTERNAL-REVIEW-porcupine-dryer-parts.html | X14: 2026-10-02 | Y14: Built (new URL). 4 GPS listings: 3 troughs and a new shaft and flights set. 'porcupine dryer' demand belongs to the live porcupine dryer page, linked from an FAQ. Parts queries have no measured volume. The GPS/Bethlehem brand angle comes from IPP's own news post (not linked). Hero opener rewritten on 2026-10-02 to the client's 'Buying ... from IPP [verb] ... while [verb]ing issues like ...' format; review doc re-issued. Live white header with the IPP logo and menu added on 2026-10-02 (adbac2f).
A15: 11 | B15: 3 | C15: Dryer-Rotary Hot Air | E15: Rotary Hot Air Dryers | F15: https://internationalprocessplants.com/process-equipment/dryer/rotary-hot-air-dryer/ | G15: https://ims.internationalprocessplants.com/inventory/search/equipment/rotary-hot-air-dryer | H15: 4 | I15: 4 | J15: 3 | K15: rotary dryer | L15: 450 | M15: Done | N15: Done | O15: Done | P15: Done | Q15: Done | R15: Done | S15: Done | T15: =IF(COUNTIF(M15:S15,"Done")+COUNTIF(M15:S15,"N/A")=7,"Ready for client review",IF(COUNTIF(M15:S15,"Blocked")>0,"Blocked",IF(COUNTIF(M15:S15,"Not started")=7,"Not started","In progress"))) -> Ready for client review | U15: Not sent | V15: https://international-process-plants-update-one.vercel.app/equipment/dryer/rotary-hot-air-dryer/ | W15: equipment/dryer/rotary-hot-air-dryer/INTERNAL-REVIEW-rotary-hot-air-dryer.html | X15: 2026-10-02 | Y15: Built from 4 units: a Standard Steel louver dryer and a Patterson Kelly unit in stainless steel 304, a Link Belt in carbon steel, and a refurbished stainless steel 316 co-current dryer. The refurbished listing says both 'direct fired' and steam; the copy uses steam. Comparison links to the live rotary steam tube dryer page. Manufacturer, design, maintenance, triple-pass and household vent terms excluded. Live white header with the IPP logo and menu added on 2026-10-02 (adbac2f).
A16: 12 | B16: 3 | C16: Dryer-Shelf | E16: Shelf Dryers | F16: https://internationalprocessplants.com/process-equipment/dryer/shelf-dryer/ | G16: https://ims.internationalprocessplants.com/inventory/search/equipment/shelf-dryer | H16: 32 | I16: 23 | J16: 20 | K16: vacuum tray dryer | L16: 200 | M16: Done | N16: Done | O16: Done | P16: Done | Q16: Done | R16: Done | S16: Done | T16: =IF(COUNTIF(M16:S16,"Done")+COUNTIF(M16:S16,"N/A")=7,"Ready for client review",IF(COUNTIF(M16:S16,"Blocked")>0,"Blocked",IF(COUNTIF(M16:S16,"Not started")=7,"Not started","In progress"))) -> Ready for client review | U16: Not sent | V16: https://international-process-plants-update-one.vercel.app/equipment/dryer/shelf-dryer/ | W16: equipment/dryer/shelf-dryer/INTERNAL-REVIEW-shelf-dryer.html | X16: 2026-10-02 | Y16: Built from 23 listings: 22 good used vacuum shelf and tray dryers and a new GPS vacuum tray dryer. The IMS shelf-dryer search also returns oven dryers; they stay off the page. The Stokes hot water generator is described as an accessory. Unit defect notes and mis-entered IMS dimensions are not repeated. The IMS Leybold manufacturer filter is broken (returns all 32), so Leybold has no tab. Pharmaceutical, rotary tray, household and parts terms excluded. Live white header with the IPP logo and menu added on 2026-10-02 (adbac2f).
A17: 13 | B17: 3 | C17: Dryer-Thin Film | E17: Thin Film Dryers | F17: https://internationalprocessplants.com/process-equipment/dryer/thin-film-dryer/ | G17: https://ims.internationalprocessplants.com/inventory/search/equipment/thin-film-dryer | H17: 15 | I17: 15 | J17: 15 | K17: thin film dryer | L17: 40 | M17: Done | N17: Done | O17: Done | P17: Done | Q17: Done | R17: Done | S17: Done | T17: =IF(COUNTIF(M17:S17,"Done")+COUNTIF(M17:S17,"N/A")=7,"Ready for client review",IF(COUNTIF(M17:S17,"Blocked")>0,"Blocked",IF(COUNTIF(M17:S17,"Not started")=7,"Not started","In progress"))) -> Ready for client review | U17: Not sent | V17: https://international-process-plants-update-one.vercel.app/equipment/dryer/thin-film-dryer/ | W17: equipment/dryer/thin-film-dryer/INTERNAL-REVIEW-thin-film-dryer.html | X17: 2026-10-02 | Y17: Built from 15 units: Luwa SMS DK600, D-850 and 1000/6000 dryers and a Buss-SMS-Canzler D-015, all stainless. IMS lists the DK600 units as coolers; an FAQ covers cooling duty. Thin film evaporator terms are excluded (IPP's evaporator page and blog own them); the comparison links to the live evaporator page. Live white header with the IPP logo and menu added on 2026-10-02 (adbac2f).
A18: 14 | B18: 3 | C18: Dryer-Thermal Disc | E18: Thermal Disc Dryers | F18: https://internationalprocessplants.com/process-equipment/dryer/thermal-disc-dryer/ | G18: https://ims.internationalprocessplants.com/inventory/search/equipment/thermal-disc-dryer | H18: 8 | I18: 8 | J18: 8 | K18: horizontal disc dryer | L18: 150 | M18: Done | N18: Done | O18: Done | P18: Done | Q18: Done | R18: Done | S18: Done | T18: =IF(COUNTIF(M18:S18,"Done")+COUNTIF(M18:S18,"N/A")=7,"Ready for client review",IF(COUNTIF(M18:S18,"Blocked")>0,"Blocked",IF(COUNTIF(M18:S18,"Not started")=7,"Not started","In progress"))) -> Ready for client review | U18: Not sent | V18: https://international-process-plants-update-one.vercel.app/equipment/dryer/thermal-disc-dryer/ | W18: equipment/dryer/thermal-disc-dryer/INTERNAL-REVIEW-thermal-disc-dryer.html | X18: 2026-10-02 | Y18: Built from 8 units: unused surplus Bepex TorusDisc TD48-9 units, a Bepex Model 60-14, a Bethlehem processor and a Strong Scott TDJ. IMS lists the TD48-9 units as coolers; unit 239472 has no IMS data. Comparison links to the live porcupine dryer page. Sludge, rendering and fish meal (application) terms excluded. Live white header with the IPP logo and menu added on 2026-10-02 (adbac2f).
A19: 15 | B19: 3 | C19: Dryer-Spherical | E19: Spherical Dryers | F19: https://internationalprocessplants.com/process-equipment/dryer/spherical-dryer/ | G19: https://ims.internationalprocessplants.com/inventory/search/equipment/spherical-dryer | H19: 3 | I19: 3 | J19: 3 | K19: spherical dryer | L19: 50 | M19: Done | N19: Done | O19: Done | P19: Done | Q19: Done | R19: Done | S19: Done | T19: =IF(COUNTIF(M19:S19,"Done")+COUNTIF(M19:S19,"N/A")=7,"Ready for client review",IF(COUNTIF(M19:S19,"Blocked")>0,"Blocked",IF(COUNTIF(M19:S19,"Not started")=7,"Not started","In progress"))) -> Ready for client review | U19: Not sent | V19: https://international-process-plants-update-one.vercel.app/equipment/dryer/spherical-dryer/ | W19: equipment/dryer/spherical-dryer/INTERNAL-REVIEW-spherical-dryer.html | X19: 2026-10-02 | Y19: Built from 3 units: two Rosenmund AG RKT-2000 dryers and a Pierre Guerin Turbosphere TS200, jacketed, stainless steel 316L. Rosenmund vessel and jacket pressures are not published (the IMS fields look swapped or inconsistent) and the IMS model field holds the town. The comparison links to the Nauta dryer page, which is new and not live yet, so publish them together. Live white header with the IPP logo and menu added on 2026-10-02 (adbac2f).
A20: 16 | B20: 4 | C20: Dryer-Pan | E20: Pan Dryers | F20: https://internationalprocessplants.com/process-equipment/dryer/pan-dryer/ | G20: https://ims.internationalprocessplants.com/inventory/search/equipment/pan-dryer | H20: 7 | I20: 7 | J20: 3 | K20: pan dryer | L20: 60 | M20: Done | N20: Done | O20: Done | P20: Done | Q20: Done | R20: Done | S20: Done | T20: =IF(COUNTIF(M20:S20,"Done")+COUNTIF(M20:S20,"N/A")=7,"Ready for client review",IF(COUNTIF(M20:S20,"Blocked")>0,"Blocked",IF(COUNTIF(M20:S20,"Not started")=7,"Not started","In progress"))) -> Ready for client review | U20: Not sent | V20: https://international-process-plants-update-one.vercel.app/equipment/dryer/pan-dryer/ | W20: equipment/dryer/pan-dryer/INTERNAL-REVIEW-pan-dryer.html | X20: 2026-10-02 | Y20: Built from 7 units: Buflovak/Blaw Knox Grainer pans (no photos on IMS), a Guedu 3500, a Bonazzi Mario 881 LT 1000 and an unbranded stainless steel 304 pan. Only design capacity is published: two listings give a working capacity above it. No listing names an agitator, so agitation is described as the design type only. Comparison links to the live rotary vacuum dryer page.
A21: 17 | B21: 4 | C21: Dryer-Oven | E21: Oven Dryers | F21: https://internationalprocessplants.com/process-equipment/dryer/oven-dryer/ | G21: https://ims.internationalprocessplants.com/inventory/search/equipment/oven-dryer | H21: 11 | I21: 11 | J21: 11 | K21: drying oven | L21: 600 | M21: Done | N21: Done | O21: Done | P21: Done | Q21: Done | R21: Done | S21: Done | T21: =IF(COUNTIF(M21:S21,"Done")+COUNTIF(M21:S21,"N/A")=7,"Ready for client review",IF(COUNTIF(M21:S21,"Blocked")>0,"Blocked",IF(COUNTIF(M21:S21,"Not started")=7,"Not started","In progress"))) -> Ready for client review | U21: Not sent | V21: https://international-process-plants-update-one.vercel.app/equipment/dryer/oven-dryer/ | W21: equipment/dryer/oven-dryer/INTERNAL-REVIEW-oven-dryer.html | X21: 2026-10-02 | Y21: Built as 'Industrial Drying Ovens' from 11 units: Hedinair and Lewco drum warming ovens, Amarc drum and IBC ovens, Barlow Whitney vacuum ovens, a Lytzen shelf oven, a Caltherm two-chamber oven and Normandie-Labo and Better Built lab ovens. The Caltherm's -16.7 C rating is an IMS error and stays off the page. The comparison links to the shelf dryer page (new URL, publish together). Lab-instrument brands and drum heater blankets are excluded.
A22: 18 | B22: 4 | C22: Dryer-Flaker Drum and Belt | E22: Flaker Drum and Belt Dryers | F22: https://internationalprocessplants.com/process-equipment/dryer/flaker-drum-and-belt-dryer/ | G22: https://ims.internationalprocessplants.com/inventory/search/equipment/flaker-drum-and-belt-dryer | H22: 24 | I22: 24 | J22: 23 | K22: drum flaker | L22: 40 | M22: Done | N22: Done | O22: Done | P22: Done | Q22: Done | R22: Done | S22: Done | T22: =IF(COUNTIF(M22:S22,"Done")+COUNTIF(M22:S22,"N/A")=7,"Ready for client review",IF(COUNTIF(M22:S22,"Blocked")>0,"Blocked",IF(COUNTIF(M22:S22,"Not started")=7,"Not started","In progress"))) -> Ready for client review | U22: Not sent | V22: https://international-process-plants-update-one.vercel.app/equipment/dryer/flaker-drum-and-belt-dryer/ | W22: equipment/dryer/flaker-drum-and-belt-dryer/INTERNAL-REVIEW-flaker-drum-and-belt-dryer.html | X22: 2026-10-02 | Y22: Built as 'Drum & Belt Flakers' from 24 listings: belt flakers and pastillators (Sandvik, Berndorf, Kaiser, Steel Belt Systems and others) and drum flakers (Simon Dryers, APV Mitchell, Blaw Knox, Gouda and others), plus two spare drums. First page with drum/belt type tabs. Three mis-entered IMS areas or widths (Simon 228 m2, APV 28 mm and 26 m2, MBT 4 m2) are kept off the cards. IMS has no drum filter, so the drum tab links to the whole category. The FAQ links the drum dryer page (new URL). Ice flakers, grain flaking mills and Jayden Flaker are excluded.
A23: 19a | B23: 4 | C23: Dryer-Air | D23: Desiccant | E23: Desiccant Air Dryers | F23: https://internationalprocessplants.com/process-equipment/dryer/desiccant/ | G23: https://ims.internationalprocessplants.com/inventory/search/equipment/air-dryer/desiccant | H23: 4 | I23: 4 | J23: 3 | K23: desiccant air dryer | L23: 1100 | M23: Done | N23: Done | O23: Done | P23: Done | Q23: Done | R23: Done | S23: Done | T23: =IF(COUNTIF(M23:S23,"Done")+COUNTIF(M23:S23,"N/A")=7,"Ready for client review",IF(COUNTIF(M23:S23,"Blocked")>0,"Blocked",IF(COUNTIF(M23:S23,"Not started")=7,"Not started","In progress"))) -> Ready for client review | U23: Not sent | V23: https://international-process-plants-update-one.vercel.app/equipment/dryer/desiccant/ | W23: equipment/dryer/desiccant/INTERNAL-REVIEW-desiccant.html | X23: 2026-10-02 | Y23: Built from 4 listings: PneumaTech PE-3100, Arrow RH212A heatless, a Sullair self-recharging dryer and one listing with no data. Dew points and purge figures come from the SERP evidence (Sullair, Atlas Copco). The comparison links the refrigerated page (new URL, publish together). Plastic resin dryers, rentals and inline cartridges are excluded.
A24: 19b | B24: 4 | C24: Dryer-Air | D24: Refrigerant/Heat | E24: Refrigerated Air Dryers | F24: https://internationalprocessplants.com/process-equipment/dryer/refrigerant-heat/ | G24: https://ims.internationalprocessplants.com/inventory/search/equipment/air-dryer/refrigerant-heat | H24: 12 | I24: 12 | J24: 12 | K24: refrigerated air dryer | L24: 1300 | M24: Done | N24: Done | O24: Done | P24: Done | Q24: Done | R24: Done | S24: Done | T24: =IF(COUNTIF(M24:S24,"Done")+COUNTIF(M24:S24,"N/A")=7,"Ready for client review",IF(COUNTIF(M24:S24,"Blocked")>0,"Blocked",IF(COUNTIF(M24:S24,"Not started")=7,"Not started","In progress"))) -> Ready for client review | U24: Not sent | V24: https://international-process-plants-update-one.vercel.app/equipment/dryer/refrigerant-heat/ | W24: equipment/dryer/refrigerant-heat/INTERNAL-REVIEW-refrigerant-heat.html | X24: 2026-10-02 | Y24: Built from 12 listings: Atlas Copco FD units, Hankinson 801600, Ingersoll Rand DXR 2000W and TS 2000, M.T.A DE235 HP and a 1000DES/HYD. The IMS category also holds an Atlas Copco CD335+ (a desiccant model, named without a type), an Oriad electric dryer and natural gas air heater skids. The IMS Ingersoll Rand filter returns the whole category, so it has no tab. The FAQ links the desiccant page (new URL).
A25: 20 | B25: 5 | C25: Heat Exchanger | D25: Air Fin | E25: Air Fin Heat Exchangers | F25: https://internationalprocessplants.com/process-equipment/heat-exchanger/air-fin/ | G25: https://ims.internationalprocessplants.com/inventory/search/equipment/heat-exchanger/air-fin | H25: 5 | I25: 5 | J25: 4 | K25: air cooled heat exchanger | L25: 300 | M25: Done | N25: Done | O25: Done | P25: Done | Q25: Done | R25: Done | S25: Done | T25: =IF(COUNTIF(M25:S25,"Done")+COUNTIF(M25:S25,"N/A")=7,"Ready for client review",IF(COUNTIF(M25:S25,"Blocked")>0,"Blocked",IF(COUNTIF(M25:S25,"Not started")=7,"Not started","In progress"))) -> Ready for client review | U25: Not sent | V25: https://international-process-plants-update-one.vercel.app/equipment/heat-exchanger/air-fin/ | W25: equipment/heat-exchanger/air-fin/INTERNAL-REVIEW-air-fin.html | X25: 2026-10-02 | Y25: Built as 'Air Cooled Heat Exchangers' from 5 units: Balke Durr fin fan coolers of 2,100 m2, Hiross Hypercool units and a Finnco ambient air vaporizer. Duty and gas-service notes stay off the page. Comparison links the live shell and tube page. Cleaning, fouling and maintenance terms are excluded (client rule).
A26: 21 | B26: 5 | C26: Heat Exchanger | D26: Block | E26: Block Heat Exchangers | F26: https://internationalprocessplants.com/process-equipment/heat-exchanger/block/ | G26: https://ims.internationalprocessplants.com/inventory/search/equipment/heat-exchanger/block | H26: 94 | I26: 94 | J26: 91 | K26: graphite heat exchanger | L26: 200 | M26: Done | N26: Done | O26: Done | P26: Done | Q26: Done | R26: Done | S26: Done | T26: =IF(COUNTIF(M26:S26,"Done")+COUNTIF(M26:S26,"N/A")=7,"Ready for client review",IF(COUNTIF(M26:S26,"Blocked")>0,"Blocked",IF(COUNTIF(M26:S26,"Not started")=7,"Not started","In progress"))) -> Ready for client review | U26: Not sent | V26: https://international-process-plants-update-one.vercel.app/equipment/heat-exchanger/block/ | W26: equipment/heat-exchanger/block/INTERNAL-REVIEW-block.html | X26: 2026-10-02 | Y26: Built as 'Graphite Block Heat Exchangers' from 94 listings: Ralph Coidan, Carbone Lorraine, Vicarb, GAB Neumann, SGL Carbon and others, plus Karbate tube units and an unused Chart BAHX. One listing's test note stays off (no-defects rule). IMS files Vicarb, Carbone and GAB units under several maker records, so those tabs link IMS keyword searches. Manufacturer domains (SGL) were kept out of the competitor set so the brand blocklist does not block them.
A27: 22 | B27: 0 | C27: Heat Exchanger | D27: Plate and Frame | E27: Plate and Frame Heat Exchangers | F27: https://internationalprocessplants.com/process-equipment/heat-exchanger/plate-and-frame/ | G27: https://ims.internationalprocessplants.com/inventory/search/equipment/heat-exchanger/plate-and-frame | H27: 161 | I27: 161 | J27: 148 | K27: plate and frame heat exchanger | L27: 1100 | M27: Done | N27: Done | O27: Done | P27: Done | Q27: Done | R27: Done | S27: Done | T27: =IF(COUNTIF(M27:S27,"Done")+COUNTIF(M27:S27,"N/A")=7,"Ready for client review",IF(COUNTIF(M27:S27,"Blocked")>0,"Blocked",IF(COUNTIF(M27:S27,"Not started")=7,"Not started","In progress"))) -> Ready for client review | U27: Not sent | V27: https://international-process-plants-update-one.vercel.app/equipment/heat-exchanger/plate-and-frame/ | W27: equipment/heat-exchanger/plate-and-frame/INTERNAL-REVIEW-plate-and-frame.html | X27: 2026-10-02 | Y27: Pilot. Rev 4 approved internally on 2026-10-01 (rev 1 copy, live reactor layout, IMS listing). It is the model for the other 39 pages. 2026-10-02: live hero, logo strip and tabs; blog and intro links removed; hero predicates varied. Hero opener rewritten on 2026-10-02 to the client's 'Buying ... from IPP [verb] ... while [verb]ing issues like ...' format; review doc re-issued. Live white header with the IPP logo and menu added on 2026-10-02 (adbac2f).
A28: 23 | B28: 5 | C28: Heat Exchanger | D28: Spiral | E28: Spiral Heat Exchangers | F28: https://internationalprocessplants.com/process-equipment/heat-exchanger/spiral/ | G28: https://ims.internationalprocessplants.com/inventory/search/equipment/heat-exchanger/spiral | H28: 67 | I28: 67 | J28: 63 | K28: spiral heat exchanger | L28: 350 | M28: Done | N28: Done | O28: Done | P28: Done | Q28: Done | R28: Done | S28: Done | T28: =IF(COUNTIF(M28:S28,"Done")+COUNTIF(M28:S28,"N/A")=7,"Ready for client review",IF(COUNTIF(M28:S28,"Blocked")>0,"Blocked",IF(COUNTIF(M28:S28,"Not started")=7,"Not started","In progress"))) -> Ready for client review | U28: Not sent | V28: https://international-process-plants-update-one.vercel.app/equipment/heat-exchanger/spiral/ | W28: equipment/heat-exchanger/spiral/INTERNAL-REVIEW-spiral.html | X28: 2026-10-02 | Y28: Built from 67 listings: Alfa Laval spiral plate units (to 205.8 m2), Kuhni coil exchangers, QVF and Schott glass, GAB Neumann graphite, GEA Canzler, American Heat Reclaiming and others. Comparison: spiral plate vs spiral tube (both in stock). Alfa Laval and American Heat Reclaiming tabs link keyword searches (spelling variants on IMS).
A29: 24 | B29: 5 | C29: Heat Exchanger | D29: Welded Plate | E29: Welded Plate Heat Exchangers | F29: https://internationalprocessplants.com/process-equipment/heat-exchanger/welded-plate/ | G29: https://ims.internationalprocessplants.com/inventory/search/equipment/heat-exchanger/welded-plate | H29: 31 | I29: 31 | J29: 30 | K29: welded plate heat exchanger | L29: 150 | M29: Done | N29: Done | O29: Done | P29: Done | Q29: Done | R29: Done | S29: Done | T29: =IF(COUNTIF(M29:S29,"Done")+COUNTIF(M29:S29,"N/A")=7,"Ready for client review",IF(COUNTIF(M29:S29,"Blocked")>0,"Blocked",IF(COUNTIF(M29:S29,"Not started")=7,"Not started","In progress"))) -> Ready for client review | U29: Not sent | V29: https://international-process-plants-update-one.vercel.app/equipment/heat-exchanger/welded-plate/ | W29: equipment/heat-exchanger/welded-plate/INTERNAL-REVIEW-welded-plate.html | X29: 2026-10-02 | Y29: Built from 31 listings: Alfa Laval Compabloc CP30, CPL30, CPL20, CPF, CPK40 and unused CPX50 and CPX75 units, plus Kapp. The CPX50 plate grade is not published (IMS fields disagree). Comparison links the plate and frame pilot page (new URL, publish together). Semi-welded terms are excluded (no units).
A30: 25 | B30: 5 | C30: Homogenizer | E30: Homogenizers | F30: https://internationalprocessplants.com/process-equipment/homogenizer/ | G30: https://ims.internationalprocessplants.com/inventory/search/equipment/homogenizer | H30: 5 | I30: 5 | J30: 5 | K30: industrial homogenizer | L30: 150 | M30: Done | N30: Done | O30: Done | P30: Done | Q30: Done | R30: Done | S30: Done | T30: =IF(COUNTIF(M30:S30,"Done")+COUNTIF(M30:S30,"N/A")=7,"Ready for client review",IF(COUNTIF(M30:S30,"Blocked")>0,"Blocked",IF(COUNTIF(M30:S30,"Not started")=7,"Not started","In progress"))) -> Ready for client review | U30: Not sent | V30: https://international-process-plants-update-one.vercel.app/equipment/homogenizer/ | W30: equipment/homogenizer/INTERNAL-REVIEW-homogenizer.html | X30: 2026-10-02 | Y30: Built as 'Industrial Homogenizers' from 5 units: SPX, Rannie and APV Gaulin high-pressure machines and BWS and Hoelschertechnik rotor-stator units, split by type tabs on IMS pressure filters. Lab-instrument and application terms are excluded; 'homogenizer' (1,500) is a lab-heavy head term.
A31: 26 | B31: 6 | C31: Incinerator | E31: Incinerators | F31: https://internationalprocessplants.com/process-equipment/incinerator/ | G31: https://ims.internationalprocessplants.com/inventory/search/equipment/incinerator | H31: 1 | I31: 1 | J31: 1 | K31: thermal oxidizer | L31: 900 | M31: Done | N31: Done | O31: Done | P31: Done | Q31: Done | R31: Done | S31: Done | T31: =IF(COUNTIF(M31:S31,"Done")+COUNTIF(M31:S31,"N/A")=7,"Ready for client review",IF(COUNTIF(M31:S31,"Blocked")>0,"Blocked",IF(COUNTIF(M31:S31,"Not started")=7,"Not started","In progress"))) -> Ready for client review | U31: Not sent | V31: https://international-process-plants-update-one.vercel.app/equipment/incinerator/ | W31: equipment/incinerator/INTERNAL-REVIEW-incinerator.html | X31: 2026-10-02 | Y31: Built as 'Incinerators & Thermal Oxidizers' around one good used Thermatrix ES-100 flameless thermal oxidizer, so the page leans on sourcing to specification. 'thermal oxidizer' (900) leads; animal, pet and cremation incinerator demand is excluded. Comparison: flameless vs direct-fired. IMS's ES-100 dimensions (47.2 m high) and 'Liquid' phase field are not credible and stay off the page.
A32: 27 | B32: 6 | C32: Kettle | E32: Kettles | F32: https://internationalprocessplants.com/process-equipment/kettle/ | G32: https://ims.internationalprocessplants.com/inventory/search/equipment/kettle | H32: 2 | I32: 2 | J32: 2 | K32: steam jacketed kettle | L32: 1000 | M32: Done | N32: Done | O32: Done | P32: Done | Q32: Done | R32: Done | S32: Done | T32: =IF(COUNTIF(M32:S32,"Done")+COUNTIF(M32:S32,"N/A")=7,"Ready for client review",IF(COUNTIF(M32:S32,"Blocked")>0,"Blocked",IF(COUNTIF(M32:S32,"Not started")=7,"Not started","In progress"))) -> Ready for client review | U32: Not sent | V32: https://international-process-plants-update-one.vercel.app/equipment/kettle/ | W32: equipment/kettle/INTERNAL-REVIEW-kettle.html | X32: 2026-10-02 | Y32: Built as 'Steam Jacketed Kettles' from two good used Groen units (TA25SP mixer kettle, TDC/2-20 table-top kettle). Foodservice brands not in stock (Cleveland, Vulcan, Market Forge) are excluded. Comparison vs jacketed reactors links the live reactor hub. IMS's TDC jacket (carbon steel) and bottom-head (stainless steel 904) fields conflict with its 304 build, so only the overall material is published.
A33: 28 | B33: 6 | C33: Kiln | E33: Kilns | F33: https://internationalprocessplants.com/process-equipment/kiln/ | G33: https://ims.internationalprocessplants.com/inventory/search/equipment/kiln | H33: 2 | I33: 2 | J33: 2 | K33: rotary kiln | L33: 2100 | M33: Done | N33: Done | O33: Done | P33: Done | Q33: Done | R33: Done | S33: Done | T33: =IF(COUNTIF(M33:S33,"Done")+COUNTIF(M33:S33,"N/A")=7,"Ready for client review",IF(COUNTIF(M33:S33,"Blocked")>0,"Blocked",IF(COUNTIF(M33:S33,"Not started")=7,"Not started","In progress"))) -> Ready for client review | U33: Not sent | V33: https://international-process-plants-update-one.vercel.app/equipment/kiln/ | W33: equipment/kiln/INTERNAL-REVIEW-kiln.html | X33: 2026-10-02 | Y33: Built as 'Rotary Kilns' from two good used units: a Bethlehem indirect-fired Inconel kiln and a nickel kiln with no maker named. 'rotary kiln' (2,100) leads; cement, lime, incineration and refractory demand is excluded. Comparison: indirect vs direct-fired. Firing type is stated only for the Bethlehem unit.
A34: 29 | B34: 6 | C34: Mill | D34: Ball | E34: Ball Mills | F34: https://internationalprocessplants.com/process-equipment/mill/ball/ | G34: https://ims.internationalprocessplants.com/inventory/search/equipment/mill/ball | H34: 8 | I34: 8 | J34: 8 | K34: ball mill | L34: 1600 | M34: Done | N34: Done | O34: Done | P34: Done | Q34: Done | R34: Done | S34: Done | T34: =IF(COUNTIF(M34:S34,"Done")+COUNTIF(M34:S34,"N/A")=7,"Ready for client review",IF(COUNTIF(M34:S34,"Blocked")>0,"Blocked",IF(COUNTIF(M34:S34,"Not started")=7,"Not started","In progress"))) -> Ready for client review | U34: Not sent | V34: https://international-process-plants-update-one.vercel.app/equipment/mill/ball/ | W34: equipment/mill/ball/INTERNAL-REVIEW-ball.html | X34: 2026-10-02 | Y34: Built from good used Blaw Knox Ni-hard lined cylindrical mills, Hardinge conical mills, a TEMA vibratory mill, a rod mill and an Engineering Plastics pilot mill, with manufacturer tabs for Blaw Knox and Hardinge. Comparison: conical vs cylindrical. IMS's 25.4 mm rod-mill diameter and the Hardinge 'approximately 470 mm' ends stay off the page; no throughput claims.
A35: 30 | B35: 6 | C35: Mill | D35: Colloid | E35: Colloid Mills | F35: https://internationalprocessplants.com/process-equipment/mill/colloid/ | G35: https://ims.internationalprocessplants.com/inventory/search/equipment/mill/colloid | H35: 14 | I35: 14 | J35: 12 | K35: colloid mill | L35: 300 | M35: Done | N35: Done | O35: Done | P35: Done | Q35: Done | R35: Done | S35: Done | T35: =IF(COUNTIF(M35:S35,"Done")+COUNTIF(M35:S35,"N/A")=7,"Ready for client review",IF(COUNTIF(M35:S35,"Blocked")>0,"Blocked",IF(COUNTIF(M35:S35,"Not started")=7,"Not started","In progress"))) -> Ready for client review | U35: Not sent | V35: https://international-process-plants-update-one.vercel.app/equipment/mill/colloid/ | W35: equipment/mill/colloid/INTERNAL-REVIEW-colloid.html | X35: 2026-10-02 | Y35: Built from IMS's mixed colloid category: rotor-stator colloid and dispersion mills (IKA-Werk, Premier), Peters & Smith attritors and Alpine, Williams, Reitz and Bepex hammer mills, split by type tabs, plus a new GPS Multi-Mill. No condition tabs. Comparison vs high-pressure homogenizers links the new homogenizer page.
A36: 31 | B36: 7 | C36: Mill | D36: Kady | E36: Kady Mills | F36: https://internationalprocessplants.com/process-equipment/mill/kady/ | G36: https://ims.internationalprocessplants.com/inventory/search/equipment/mill/kady | H36: 1 | I36: 1 | J36: 1 | K36: kady mill | L36: 50 | M36: Done | N36: Done | O36: Done | P36: Done | Q36: Done | R36: Done | S36: Done | T36: =IF(COUNTIF(M36:S36,"Done")+COUNTIF(M36:S36,"N/A")=7,"Ready for client review",IF(COUNTIF(M36:S36,"Blocked")>0,"Blocked",IF(COUNTIF(M36:S36,"Not started")=7,"Not started","In progress"))) -> Ready for client review | U36: Not sent | V36: https://international-process-plants-update-one.vercel.app/equipment/mill/kady/ | W36: equipment/mill/kady/INTERNAL-REVIEW-kady.html | X36: 2026-10-02 | Y36: IMS's Kady category holds no Kady dispersion mill: its listing is a Powtec RTS 350 x 300 rotor sieving mill, so the page is built as 'Kady & Rotor Sieve Mills', names the Powtec for what it is and offers Kady mills through sourcing to specification. 'kady mill' (50) is the only measurable machine term ('kady' alone is people's names). The listing's ATEX/Ex wording, motor marking and throughput figure stay off the page.
A37: 32 | B37: 7 | C37: Mill | D37: Pebble | E37: Pebble Mills | F37: https://internationalprocessplants.com/process-equipment/mill/pebble/ | G37: https://ims.internationalprocessplants.com/inventory/search/equipment/mill/pebble | H37: 0 | I37: 0 | J37: 0 | K37: pebble mills | L37: 80 | M37: Done | N37: Done | O37: Done | P37: Done | Q37: Done | R37: Done | S37: Done | T37: =IF(COUNTIF(M37:S37,"Done")+COUNTIF(M37:S37,"N/A")=7,"Ready for client review",IF(COUNTIF(M37:S37,"Blocked")>0,"Blocked",IF(COUNTIF(M37:S37,"Not started")=7,"Not started","In progress"))) -> Ready for client review | U37: Not sent | V37: https://international-process-plants-update-one.vercel.app/equipment/mill/pebble/ | W37: equipment/mill/pebble/INTERNAL-REVIEW-pebble.html | X37: 2026-10-02 | Y37: IMS lists no pebble mills, so this is a sourcing page: a sourcing block replaces the IMS listing (new builder option), the hero and closing search point at IMS's full mill category, and business copy that assumes stock is rewritten. It links IPP's new ball mill page by relative path (resolves once P29 is published) and names the TEMA vibratory mill whose listing accepts pebble media. Rebuild the page if IMS lists a pebble mill.
A38: 33 | B38: 7 | C38: Mill | D38: Pellet | E38: Pellet Mills | F38: https://internationalprocessplants.com/process-equipment/mill/pellet/ | G38: https://ims.internationalprocessplants.com/inventory/search/equipment/mill/pellet | H38: 2 | I38: 2 | J38: 2 | K38: pelletizer | L38: 600 | M38: Done | N38: Done | O38: Done | P38: Done | Q38: Done | R38: Done | S38: Done | T38: =IF(COUNTIF(M38:S38,"Done")+COUNTIF(M38:S38,"N/A")=7,"Ready for client review",IF(COUNTIF(M38:S38,"Blocked")>0,"Blocked",IF(COUNTIF(M38:S38,"Not started")=7,"Not started","In progress"))) -> Ready for client review | U38: Not sent | V38: https://international-process-plants-update-one.vercel.app/equipment/mill/pellet/ | W38: equipment/mill/pellet/INTERNAL-REVIEW-pellet.html | X38: 2026-10-02 | Y38: IMS's pellet mill category holds a Black Clawson underwater pelletizing system (Gala spin dryer, MAAG gear pump, Kenics exchanger) and a Baker Perkins centrifugal pelletizer, not ring-die or flat-die pellet mills, so the page is built as 'Pelletizers'. Feed, wood and biomass pellet mill demand gets one FAQ (sourcing) and is otherwise excluded. A hero card opens IMS's site-wide pelletizer search (waterslide and Rieter (Maag) strand units in the plastics categories).
A39: 34 | B39: 7 | C39: Mill | D39: Roll | E39: Roll Mills | F39: https://internationalprocessplants.com/process-equipment/mill/roll/ | G39: https://ims.internationalprocessplants.com/inventory/search/equipment/mill/roll | H39: 6 | I39: 6 | J39: 5 | K39: roll mill | L39: 150 | M39: Done | N39: Done | O39: Done | P39: Done | Q39: Done | R39: Done | S39: Done | T39: =IF(COUNTIF(M39:S39,"Done")+COUNTIF(M39:S39,"N/A")=7,"Ready for client review",IF(COUNTIF(M39:S39,"Blocked")>0,"Blocked",IF(COUNTIF(M39:S39,"Not started")=7,"Not started","In progress"))) -> Ready for client review | U39: Not sent | V39: https://international-process-plants-update-one.vercel.app/equipment/mill/roll/ | W39: equipment/mill/roll/INTERNAL-REVIEW-roll.html | X39: 2026-10-02 | Y39: Two-roll mills (lab, Farrel, chrome, unused and carbon steel) and a Gundlach 4080S two-roll crusher, with good used and unused condition tabs. Grain roller mills, three-roll mills and metal rolling mills are excluded. IMS spells the maker 'Farrell'; the copy uses Farrel. The crusher's previous use stays off the page.
A40: 35 | B40: 7 | C40: Mill | D40: Shot And Sand | E40: Shot and Sand Mills | F40: https://internationalprocessplants.com/process-equipment/mill/shot-and-sand/ | G40: https://ims.internationalprocessplants.com/inventory/search/equipment/mill/shot-and-sand | H40: 33 | I40: 33 | J40: 33 | K40: bead mill | L40: 250 | M40: Done | N40: Done | O40: Done | P40: Done | Q40: Done | R40: Done | S40: Done | T40: =IF(COUNTIF(M40:S40,"Done")+COUNTIF(M40:S40,"N/A")=7,"Ready for client review",IF(COUNTIF(M40:S40,"Blocked")>0,"Blocked",IF(COUNTIF(M40:S40,"Not started")=7,"Not started","In progress"))) -> Ready for client review | U40: Not sent | V40: https://international-process-plants-update-one.vercel.app/equipment/mill/shot-and-sand/ | W40: equipment/mill/shot-and-sand/INTERNAL-REVIEW-shot-and-sand.html | X40: 2026-10-02 | Y40: Built as 'Bead & Sand Mills' from IMS's shot and sand category: Netzsch LMC, LME and LMJ, WAB Dyno-Mill, Asada, FrymaKoruma and Drais bead mills, Moorhouse and Premier-type sandmill systems and Union Process Szegvari attritors, plus rebuilt Netzsch seals and an unused drive part. Type tabs and Netzsch, WAB and Asada manufacturer tabs; no condition tabs, since the refurbished and unused items are parts. Bead mill homogenizers and basket mills are excluded; media-volume fields, hazardous-area wording and throughput figures stay off the page.
A41: 36 | B41: 8 | C41: Mixer-Banbury | E41: Banbury Mixers | F41: https://internationalprocessplants.com/process-equipment/mixer/banbury-mixer/ | G41: https://ims.internationalprocessplants.com/inventory/search/equipment/banbury-mixer | H41: 9 | M41: Not started | N41: Not started | O41: Not started | P41: Not started | Q41: Not started | R41: Not started | S41: Not started | T41: =IF(COUNTIF(M41:S41,"Done")+COUNTIF(M41:S41,"N/A")=7,"Ready for client review",IF(COUNTIF(M41:S41,"Blocked")>0,"Blocked",IF(COUNTIF(M41:S41,"Not started")=7,"Not started","In progress"))) -> Not started | U41: Not sent | W41: equipment/mixer/banbury-mixer/INTERNAL-REVIEW-banbury-mixer.html
...

Sheet Summary
A1: Summary
A2: Every figure on this sheet is a formula over the Pages sheet.
A4: Measure | B4: Value
A5: Pages in scope | B5: =COUNTA(Pages!$A$5:$A$44) -> 40
A6: Ready for client review | B6: =COUNTIF(Pages!$T$5:$T$44,"Ready for client review") -> 36
A7: In progress | B7: =COUNTIF(Pages!$T$5:$T$44,"In progress") -> 0
A8: Not started | B8: =COUNTIF(Pages!$T$5:$T$44,"Not started") -> 4
A9: Blocked | B9: =COUNTIF(Pages!$T$5:$T$44,"Blocked") -> 0
A10: Approved by client | B10: =COUNTIF(Pages!$U$5:$U$44,"Approved") -> 0
A11: Changes requested by client | B11: =COUNTIF(Pages!$U$5:$U$44,"Changes requested") -> 0
A12: IMS units captured so far | B12: =SUM(Pages!$I$5:$I$44) -> 724
A14: Progress by stage
A15: Stage | B15: Done | C15: Share of pages
A16: IMS Inventory Scrape | B16: =COUNTIF(Pages!$M$5:$M$44,"Done") -> 36 | C16: =IF($B$5=0,0,B16/$B$5) -> 0.9
A17: Query Network (Ahrefs) | B17: =COUNTIF(Pages!$N$5:$N$44,"Done") -> 36 | C17: =IF($B$5=0,0,B17/$B$5) -> 0.9
A18: Content Written | B18: =COUNTIF(Pages!$O$5:$O$44,"Done") -> 36 | C18: =IF($B$5=0,0,B18/$B$5) -> 0.9
A19: Content Checks | B19: =COUNTIF(Pages!$P$5:$P$44,"Done") -> 36 | C19: =IF($B$5=0,0,B19/$B$5) -> 0.9
A20: Page Built | B20: =COUNTIF(Pages!$Q$5:$Q$44,"Done") -> 36 | C20: =IF($B$5=0,0,B20/$B$5) -> 0.9
A21: Client Review Doc | B21: =COUNTIF(Pages!$R$5:$R$44,"Done") -> 36 | C21: =IF($B$5=0,0,B21/$B$5) -> 0.9
A22: Deployed to Vercel | B22: =COUNTIF(Pages!$S$5:$S$44,"Done") -> 36 | C22: =IF($B$5=0,0,B22/$B$5) -> 0.9
A24: Progress by batch (5 pages per batch; batch 0 = pilot)
A25: Batch | B25: Pages | C25: Ready for client review | D25: Approved | E25: Batch status
A26: 0 | B26: =COUNTIF(Pages!$B$5:$B$44,A26) -> 1 | C26: =COUNTIFS(Pages!$B$5:$B$44,A26,Pages!$T$5:$T$44,"Ready for client review") -> 1 | D26: =COUNTIFS(Pages!$B$5:$B$44,A26,Pages!$U$5:$U$44,"Approved") -> 0 | E26: =IF(D26=B26,"Approved",IF(C26=B26,"Ready for client review",IF(C26>0,"In progress",IF(COUNTIFS(Pages!$B$5:$B$44,A26,Pages!$T$5:$T$44,"In progress")>0,"In progress","Not started")))) -> Ready for client review
A27: 1 | B27: =COUNTIF(Pages!$B$5:$B$44,A27) -> 5 | C27: =COUNTIFS(Pages!$B$5:$B$44,A27,Pages!$T$5:$T$44,"Ready for client review") -> 5 | D27: =COUNTIFS(Pages!$B$5:$B$44,A27,Pages!$U$5:$U$44,"Approved") -> 0 | E27: =IF(D27=B27,"Approved",IF(C27=B27,"Ready for client review",IF(C27>0,"In progress",IF(COUNTIFS(Pages!$B$5:$B$44,A27,Pages!$T$5:$T$44,"In progress")>0,"In progress","Not started")))) -> Ready for client review
A28: 2 | B28: =COUNTIF(Pages!$B$5:$B$44,A28) -> 5 | C28: =COUNTIFS(Pages!$B$5:$B$44,A28,Pages!$T$5:$T$44,"Ready for client review") -> 5 | D28: =COUNTIFS(Pages!$B$5:$B$44,A28,Pages!$U$5:$U$44,"Approved") -> 0 | E28: =IF(D28=B28,"Approved",IF(C28=B28,"Ready for client review",IF(C28>0,"In progress",IF(COUNTIFS(Pages!$B$5:$B$44,A28,Pages!$T$5:$T$44,"In progress")>0,"In progress","Not started")))) -> Ready for client review
A29: 3 | B29: =COUNTIF(Pages!$B$5:$B$44,A29) -> 5 | C29: =COUNTIFS(Pages!$B$5:$B$44,A29,Pages!$T$5:$T$44,"Ready for client review") -> 5 | D29: =COUNTIFS(Pages!$B$5:$B$44,A29,Pages!$U$5:$U$44,"Approved") -> 0 | E29: =IF(D29=B29,"Approved",IF(C29=B29,"Ready for client review",IF(C29>0,"In progress",IF(COUNTIFS(Pages!$B$5:$B$44,A29,Pages!$T$5:$T$44,"In progress")>0,"In progress","Not started")))) -> Ready for client review
A30: 4 | B30: =COUNTIF(Pages!$B$5:$B$44,A30) -> 5 | C30: =COUNTIFS(Pages!$B$5:$B$44,A30,Pages!$T$5:$T$44,"Ready for client review") -> 5 | D30: =COUNTIFS(Pages!$B$5:$B$44,A30,Pages!$U$5:$U$44,"Approved") -> 0 | E30: =IF(D30=B30,"Approved",IF(C30=B30,"Ready for client review",IF(C30>0,"In progress",IF(COUNTIFS(Pages!$B$5:$B$44,A30,Pages!$T$5:$T$44,"In progress")>0,"In progress","Not started")))) -> Ready for client review
A31: 5 | B31: =COUNTIF(Pages!$B$5:$B$44,A31) -> 5 | C31: =COUNTIFS(Pages!$B$5:$B$44,A31,Pages!$T$5:$T$44,"Ready for client review") -> 5 | D31: =COUNTIFS(Pages!$B$5:$B$44,A31,Pages!$U$5:$U$44,"Approved") -> 0 | E31: =IF(D31=B31,"Approved",IF(C31=B31,"Ready for client review",IF(C31>0,"In progress",IF(COUNTIFS(Pages!$B$5:$B$44,A31,Pages!$T$5:$T$44,"In progress")>0,"In progress","Not started")))) -> Ready for client review
A32: 6 | B32: =COUNTIF(Pages!$B$5:$B$44,A32) -> 5 | C32: =COUNTIFS(Pages!$B$5:$B$44,A32,Pages!$T$5:$T$44,"Ready for client review") -> 5 | D32: =COUNTIFS(Pages!$B$5:$B$44,A32,Pages!$U$5:$U$44,"Approved") -> 0 | E32: =IF(D32=B32,"Approved",IF(C32=B32,"Ready for client review",IF(C32>0,"In progress",IF(COUNTIFS(Pages!$B$5:$B$44,A32,Pages!$T$5:$T$44,"In progress")>0,"In progress","Not started")))) -> Ready for client review
A33: 7 | B33: =COUNTIF(Pages!$B$5:$B$44,A33) -> 5 | C33: =COUNTIFS(Pages!$B$5:$B$44,A33,Pages!$T$5:$T$44,"Ready for client review") -> 5 | D33: =COUNTIFS(Pages!$B$5:$B$44,A33,Pages!$U$5:$U$44,"Approved") -> 0 | E33: =IF(D33=B33,"Approved",IF(C33=B33,"Ready for client review",IF(C33>0,"In progress",IF(COUNTIFS(Pages!$B$5:$B$44,A33,Pages!$T$5:$T$44,"In progress")>0,"In progress","Not started")))) -> Ready for client review
A34: 8 | B34: =COUNTIF(Pages!$B$5:$B$44,A34) -> 4 | C34: =COUNTIFS(Pages!$B$5:$B$44,A34,Pages!$T$5:$T$44,"Ready for client review") -> 0 | D34: =COUNTIFS(Pages!$B$5:$B$44,A34,Pages!$U$5:$U$44,"Approved") -> 0 | E34: =IF(D34=B34,"Approved",IF(C34=B34,"Ready for client review",IF(C34>0,"In progress",IF(COUNTIFS(Pages!$B$5:$B$44,A34,Pages!$T$5:$T$44,"In progress")>0,"In progress","Not started")))) -> Not started

Sheet Legend
A1: How to read and edit this tracker
A3: Stage values | B3: Not started / In progress / Done / Blocked / N/A (drop-down). Overall Status is computed: all seven stages Done (or N/A) = Ready for client review.
A4: IMS Inventory Scrape | B4: Every unit IMS lists for the category, in IMS's own Featured order, with all detail-page attributes and the IMS photo. Stored in the repo under data/<group>/<page>/.
A5: Query Network (Ahrefs) | B5: Direct and authority query networks with US volumes, plus the excluded queries and why. Shipped in each page's brief workbook.
A6: Content Written | B6: Sections written with the anup-commercial-content pipeline in the approved pilot style (rev 1 copy, live reactor layout).
A7: Content Checks | B7: section_check.py per section and whole page with no blocking findings, plus the IPP page checker (no em dashes, no 'Unknown', dual units, absolute contact links, no exact stock counts).
A8: Page Built | B8: HTML page in the live reactor-hub layout: logo strip, IMS-style listing with filters, browse cards, tabs, FAQ, brand JSON-LD.
A9: Client Review Doc | B9: Word document of the page copy for the client, in docs/new-pages-for-review/ in the repo.
A10: Deployed to Vercel | B10: Pushed to access-op-digital/international-process-plants-updated main; Vercel deploys automatically. The review URL is noindex.
A11: IMS Listing Count | B11: What IMS's category search reports on the capture date. Units on Page can be lower when IMS's search also returns a neighbouring type (for example shelf-dryer search returns oven dryers, pusher-centrifuge returns its parts-only subtype).
A12: Yellow columns | B12: Client Review and Notes / Risks are for the IPP team. Everything else is overwritten when the tracker is regenerated after each batch.
A13: Example row | B13: Priority 22, Plate and Frame Heat Exchangers (the pilot): all seven stages Done, so Overall Status reads Ready for client review and the Vercel review page is linked.
A15: Generated | B15: 2026-10-02
